File: Material Science Lab/ASEN1022_Feb21_Brittle_Data.csv
"File Path: E:\Test Run 1 02-21-20 12 55 55 PM\DAQ- Crosshead, … - (Timed).csv   "
"Test: MTS EM Tension (Extensometer)_ASEN1022_cast 32"
"Test Run: Test Run 1"
"Date: 2/21/2020 12:51:31 PM"
""
""
"Crosshead ","Load ","Time ","Extensometer "
"in","lbf","sec","in"
"5.74670045932903E-05","26.4440129404762","0.194999992847443","2.51877958560289E-07"
"0.00015005273272386","27.3971732213212","0.395000010728836","7.88833215720864E-08"
"0.000239445856947903","28.7292938168024","0.595000028610229","2.0529658113482E-06"
"0.00034001312617581","34.0481335910146","0.795000016689301","8.41096627167229E-06"
"0.000426213601734728","40.4917727494186","0.995000004768372","1.51464582258781E-05"
"0.000547532854541242","50.0533221837423","1.19500005245209","2.58910023779129E-05"
"0.000651292736627396","58.7892812191933","1.39499998092651","3.64895003451782E-05"
"0.000778997179343526","69.7811610884902","1.59500002861023","4.51343235751457E-05"
"0.000869986609996692","77.8679712655542","1.79499995708466","5.12551647319007E-05"
"0.000984920601279834","87.9592638194289","1.99500000476837","5.38431113168407E-05"
"0.00107271741907475","95.9760132992599","2.1949999332428","5.87732350276934E-05"
"0.00117966991401915","105.076823775095","2.39499998092651","6.72290024175616E-05"
"0.00127385188591681","113.184202104363","2.59500002861023","7.46308301597138E-05"
"0.00137920818185272","121.683054527326","2.79500007629395","7.7912096372085E-05"
"0.00147817910884463","129.620522630617","2.99499988555908","8.22754688175967E-05"
"0.00157395735136453","136.862831097418","3.1949999332428","8.77805346171381E-05"
"0.00168410245916718","145.238734268999","3.39499998092651","9.26810460398661E-05"
"0.00178147711553684","152.548139643256","3.59500002861023","9.90475805660327E-05"
"0.00189481490781149","160.542976288484","3.79500007629395","0.000105012138127798"
"0.00198261165399266","166.542057271245","3.99499988555908","0.000106942486921994"
"0.00209435303241755","174.517986035395","4.19500017166138","0.000112753191280617"
"0.00217736096673198","179.665896780895","4.39499998092651","0.000114787550103749"
"0.00228910234515687","187.637983595333","4.59499979019165","0.000119324469535316"
"0.00237689923456555","193.099342552269","4.79500007629395","0.000121219485892624"
"0.00248225538727395","200.472496849233","4.99499988555908","0.000128249450254792"
"0.00257643750239912","206.448649624968","5.19500017166138","0.000132484061166935"
"0.00267700470001327","213.291052290582","5.39499998092651","0.000136967834239797"
"0.00278714980781592","220.474784745536","5.59499979019165","0.000142533118256453"
"0.00288771700543007","227.17312801823","5.79500007629395","0.000147027633392722"
"0.00299307315813847","233.557474229529","5.99499988555908","0.000153102923724773"
"0.00308086990431963","238.940622067344","6.19500017166138","0.000156726633490973"
"0.00319261142597204","246.383329375329","6.39499998092651","0.00016121230432837"
"0.00327721563090871","250.964140900961","6.59499979019165","0.000170005918564101"
"0.00339055327995585","258.564313262109","6.79500007629395","0.000174667311655394"
"0.00347835002613701","263.42846857894","6.99499988555908","0.000175447847885969"
"0.00358689900654493","270.742635226589","7.19500017166138","0.000184382039924816"
"0.00367469575272609","275.273501405975","7.39499998092651","0.000190262889957484"
"0.00378005190543449","282.16058045823","7.59499979019165","0.000196689114549315"
"0.00388381164429313","287.952511745315","7.79500007629395","0.000199485667529754"
"0.00399076421085129","294.447794254524","7.99499988555908","0.000204286510507507"
"0.0040929278223152","299.850590920862","8.19499969482422","0.000210438794579025"
"0.00418391710974085","305.109616340508","8.39500045776367","0.000215277485426847"
"0.00428927326244925","311.121416921064","8.59500026702881","0.000221434657137216"
"0.00437547388123568","315.215865055759","8.79500007629395","0.000227216984545005"
"0.00449200407152731","322.231128015878","8.99499988555908","0.000231833923397234"
"0.0045798011041635","325.742944476872","9.19499969482422","0.000234203157095352"
"0.00468994621196615","332.268496061306","9.39500045776367","0.000238552779699703"
"0.00477774295814731","335.756657089079","9.59500026702881","0.000244399935460153"
"0.00488788806594996","342.069200004526","9.79500007629395","0.000251553916944352"
"0.00498366659492489","346.418314520076","9.99499988555908","0.000255887909846446"
"0.00509540754366725","352.568178307752","10.1949996948242","0.000263248908795933"
"0.00519118607264217","356.645859076208","10.3950004577637","0.000267131931972772"
"0.00528536790131232","361.750712542444","10.5950002670288","0.000270370485055523"
"0.00538912821308101","366.59285897593","10.7950000762939","0.000277427787969061"
"0.00547852108665691","370.792741187698","10.9949998855591","0.00028166155741957"
"0.0055870697806098","376.125724139285","11.1949996948242","0.000287272960695119"
"0.00567646322709574","379.819017839137","11.3950004577637","0.000289347324752722"
"0.0057882041758381","385.854199427935","11.5950002670288","0.000297467393709409"
"0.00587759762232405","389.064560049092","11.7950000762939","0.000302411249357983"
"0.00598933914397645","394.962391935715","11.9949998855591","0.000308496735698551"
"0.00608671380034611","398.466304957304","12.1949996948242","0.000316256121972917"
"0.00619845474908847","404.479066025287","12.3950004577637","0.000320466366304565"
"0.00628784819557442","407.363382328455","12.5950002670288","0.000322982264975064"
"0.00638681897933881","412.80945581404","12.7950000762939","0.000327442333894675"
"0.0064857897631032","416.725417942153","12.9949998855591","0.000332350024596447"
"0.0065799721646834","420.735590165683","13.1949996948242","0.000337797503984409"
"0.00668852085863629","425.32924478035","13.3950004577637","0.000340622666660388"
"0.00677951043251697","429.16276964466","13.5950002670288","0.00034731522281095"
"0.00688646299907512","434.124510484155","13.7950000762939","0.000350101248569251"
"0.00697425974525629","437.259047483512","13.9949998855591","0.000354954405395794"
"0.00708919352169816","443.102049259257","14.1949996948242","0.000362197671330343"
"0.00718656817806782","446.229780519126","14.3950004577637","0.000367787769513469"
"0.00729990582711496","451.805217939986","14.5950002670288","0.000372572678430501"
"0.00738770257329612","454.471613367036","14.7950000762939","0.000374001766739259"
"0.00749146231215477","459.770896931156","14.9949998855591","0.000380735214344523"
"0.00758564471373496","463.071790353007","15.1949996948242","0.000381157198402019"
"0.00768142324270989","467.457430833311","15.3950004577637","0.000386811963806853"
"0.00778677910896326","471.764805309499","15.5950002670288","0.000391833699415126"
"0.00787936481023867","475.567567133622","15.7950000762939","0.000398038816535167"
"0.00798631737679683","480.154031813829","15.9949998855591","0.00040169161938976"
"0.00807571025037273","483.22599991789","16.1949996948242","0.000404457700717003"
"0.00818904789941987","488.796333034133","16.3950004577637","0.000411504422698086"
"0.00828323030100006","492.014185457227","16.5949993133545","0.000414073029093034"
"0.00839816407744193","497.209763821643","16.7950000762939","0.000418199556943865"
"0.0084859608236231","499.689193510249","16.9950008392334","0.000421223877475406"
"0.00859131726278652","504.750029209794","17.1949996948242","0.000427894197554716"
"0.00868549909145667","507.932096615578","17.3950004577637","0.000429097451883786"
"0.00878606657552584","512.361096242623","17.5949993133545","0.000434312186564601"
"0.00888663348668497","515.883176197846","17.7950000762939","0.000439825407380612"
"0.00898081588826516","520.220078801814","17.9950008392334","0.000443846770430691"
"0.00908457562712381","523.893202265682","18.1949996948242","0.000449389281272925"
"0.00917556520100448","527.711002578675","18.3950004577637","0.000451080583349442"
"0.00929049897744636","532.32501952681","18.5949993133545","0.000456839833224346"
"0.00938468137902655","535.226844143662","18.7950000762939","0.000459963195580498"
"0.00949642232776891","539.97132272699","18.9950008392334","0.000465398930312468"
"0.00958262294655534","542.609424938667","19.1949996948242","0.000469474111100215"
"0.00969117221341828","547.952369517005","19.3950004577637","0.000474533193282266"
"0.00978375791469369","550.178395179661","19.5949993133545","0.000476393432209294"
"0.00988751765355233","555.109592518952","19.7950000762939","0.0004818263381979"
"0.00998489173701194","558.056148407441","19.9950008392334","0.000483982950654321"
"0.0100838630936864","562.240306067892","20.1949996948242","0.000489648995225732"
"0.0101844305777556","565.799872475297","20.3950004577637","0.000493857055337821"
"0.010277016279031","569.163609217424","20.5949993133545","0.000495476313975757"
"0.0103887578006834","573.978285710475","20.7950000762939","0.000497490056988868"
"0.0104845357567483","576.89229479641","20.9950008392334","0.000501091763428522"
"0.0105962772784007","581.442590264336","21.1949996948242","0.000509234963628412"
"0.0106840734516718","583.897431474791","21.3950004577637","0.000509650717289132"
"0.0107926227185347","588.917871817373","21.5949993133545","0.000514589953850441"
"0.0108804200376259","591.033578638322","21.7950000762939","0.000518013628492568"
"0.010987372031274","596.181901021291","21.9950008392334","0.000522582371286978"
"0.0110831499873389","598.742780043773","22.1949996948242","0.000524250398892781"
"0.0111853135988028","603.373975995617","22.3950004577637","0.000529912397286976"
"0.0112826888280825","606.494846631002","22.5949993133545","0.000531050805359947"
"0.0113800629115421","610.166213775002","22.7950000762939","0.000534898254403471"
"0.0114886121784051","614.505202008814","22.9950008392334","0.000543452410142425"
"0.0115859862618647","618.149181539873","23.1949996948242","0.000543453269507498"
"0.0116945355287276","622.040143552365","23.3950004577637","0.000548188729125981"
"0.0117823317019988","624.682636563713","23.5949993133545","0.000552085842309322"
"0.0118924770962564","629.848467260365","23.7950000762939","0.000555237205644087"
"0.0119802744153476","631.965710861198","23.9950008392334","0.000557904603215499"
"0.0120888225363905","637.084889311358","24.1949996948242","0.000562339177637959"
"0.0121798121102712","639.301200329744","24.3950004577637","0.000563344885420978"
"0.0122851691223446","643.962308604339","24.5949993133545","0.000567839472171004"
"0.0123825432058042","646.562485283868","24.7950000762939","0.000573099681586907"
"0.0124847068172682","650.930836990472","24.9950008392334","0.000575825659210764"
"0.0125900626835215","654.583598120871","25.1949996948242","0.000579824642962079"
"0.0126906301675907","658.367589276405","25.3950004577637","0.000582151373895985"
"0.0127943899064493","661.874905167738","25.5949993133545","0.000586964999929191"
"0.0128821872255406","664.91772933899","25.7950000762939","0.000589294058310169"
"0.0129907353465834","669.816270105736","25.9950008392334","0.000593962988749286"
"0.0130785326656746","672.213756495502","26.1949996948242","0.000595049942338539"
"0.013190274187327","677.435624772942","26.3950004577637","0.000598819045932949"
"0.0132796664879929","679.621968583581","26.5949993133545","0.000600981136841707"
"0.0133866196274611","684.403439654128","26.7950000762939","0.000606491815369378"
"0.0134776092013418","686.955043112308","26.9950008392334","0.000611254774670183"
"0.0135813689402004","691.545514397213","27.1949996948242","0.00061359740385793"
"0.0136883209338485","695.205849657043","27.3950004577637","0.000615862117279101"
"0.013793677945922","699.545551395801","27.5949993133545","0.000618257669032566"
"0.0138926481567763","702.565762948752","27.7950000762939","0.00062335706975927"
"0.0139852338580517","705.750739259318","27.9950008392334","0.000626135182197528"
"0.0140905897243051","710.173591766825","28.1949996948242","0.000631051896232562"
"0.0141783870433963","712.449453005734","28.3950004577637","0.000632354120772486"
"0.014288532437654","717.222032706949","28.5949993133545","0.000637886641495751"
"0.0143779258841399","719.937961842776","28.7950000762939","0.000637668935677374"
"0.0144880701325775","725.296054679975","28.9950008392334","0.000642383054396556"
"0.0145774635790635","727.353363865314","29.1949996948242","0.000643806377797952"
"0.0146844155727116","732.362113703775","29.3950004577637","0.000647872606866194"
"0.0147849830567807","735.477331184585","29.5949993133545","0.000652663065849319"
"0.0148935323236437","740.074882633958","29.7950000762939","0.000656269033307459"
"0.014992502534498","742.73554257894","29.9950008392334","0.000658291978688221"
"0.015088281636383","746.870742823071","30.1949996948242","0.000658562249003536"
"0.0151904452478469","750.796721462931","30.3950004577637","0.000662587944685856"
"0.0152814348217276","753.850138438386","30.5949993133545","0.00066659509240536"
"0.0153915790701652","758.818986884847","30.7950000762939","0.000670789939779458"
"0.0154793763892564","761.117186317077","30.9950008392334","0.00067180248667618"
"0.0155879245102992","766.588836210739","31.1949996948242","0.00067608133698612"
"0.0156757218293904","768.574849786438","31.3950004577637","0.0006801012319542"
"0.0157890594784376","774.319826959552","31.5949993133545","0.000685456723472521"
"0.0158864347077173","776.832626725649","31.7950000762939","0.000686140921297776"
"0.0159949828287601","781.908336259077","31.9950008392334","0.000689143328019968"
"0.0160875685300355","784.369105049085","32.1949996948242","0.000693794713088854"
"0.01618653988671","788.794811576377","32.3950004577637","0.000693972530045114"
"0.0162887034981739","792.969419247546","32.5950012207031","0.000695853536961395"
"0.016382885326844","796.101486422089","32.7949981689453","0.000700591431447583"
"0.0164898373204921","800.711222340547","32.9949989318848","0.000703286328701317"
"0.0165808268943728","803.382914169699","33.1949996948242","0.000706248560106367"
"0.0166893761612358","808.452696123572","33.3950004577637","0.000710876885545807"
"0.0167755762071121","810.533660742133","33.5950012207031","0.000714971831730222"
"0.0168873177287645","816.769584203339","33.7949981689453","0.000717645602925923"
"0.0169830956848294","819.069210645462","33.9949989318848","0.000722938217566437"
"0.0170980306070914","824.789050490466","34.1949996948242","0.000724364906814367"
"0.0171874229077572","827.032968661777","34.3950004577637","0.00072773125464478"
"0.0172879903918264","831.400222668463","34.5950012207031","0.000730299682005338"
"0.0173853656211061","834.754134996329","34.7949981689453","0.000733929067161704"
"0.0174795474497763","838.224238860459","34.9949989318848","0.000738063687366969"
"0.0175896928440339","843.321243772286","35.1949996948242","0.000741280648902271"
"0.0176806812720945","846.08854526425","35.3950004577637","0.00074498043038083"
"0.0177876344115627","851.081872418871","35.5950012207031","0.000749589133651113"
"0.0178754305848338","853.68616547309","35.7949981689453","0.000751085646311188"
"0.0179919616344906","859.878400477581","35.9949989318848","0.00075476852694332"
"0.018084547335766","862.104755450212","36.1949996948242","0.000757401836366855"
"0.0181978849848131","867.749457735865","36.3950004577637","0.000763072786480555"
"0.0182856811580842","869.612638690798","36.5950012207031","0.000764814576255084"
"0.018389442042763","875.200315465737","36.7949981689453","0.000771818186755028"
"0.0184852199988278","878.119648396273","36.9949989318848","0.000770147079757715"
"0.0185825940822874","882.080149698537","37.1949996948242","0.000774007204436059"
"0.0186847576937514","886.270728903505","37.3950004577637","0.000778618700642828"
"0.0187773433950268","889.485562651826","37.5950012207031","0.000780371948618324"
"0.0188858926618897","894.751393810961","37.7949981689453","0.000786248286984362"
"0.0189752861083757","897.161174439802","37.9949989318848","0.00078826371292074"
"0.0190902198848175","902.903901328086","38.1949996948242","0.000795026486359104"
"0.0191844017134877","905.631795393013","38.3950004577637","0.000794142629381995"
"0.0193009316173243","911.077155373651","38.5950012207031","0.000802464863971998"
"0.0193839394084112","912.929304444414","38.7949981689453","0.000803714524014985"
"0.0194892952746646","918.386739124144","38.9949989318848","0.000808860115614338"
"0.0195818821217601","921.370122844865","39.1949996948242","0.000810573474727718"
"0.019684045733224","926.056313562575","39.3950004577637","0.000814970559348888"
"0.0197862093446879","929.717472097343","39.5950012207031","0.000817138737426909"
"0.0198787939001432","933.10793783246","39.7949981689453","0.000820556790389187"
"0.0199825547848219","937.770967081911","39.9949989318848","0.000825495704688594"
"0.0200735443587026","940.685140822835","40.1949996948242","0.000829805134072365"
"0.0201916715357541","946.633247365678","40.3950004577637","0.000833541653407774"
"0.0202874483459988","949.481229801578","40.5950012207031","0.000838058619456564"
"0.020400785995046","954.952715040252","40.7949981689453","0.000840092450128245"
"0.0204853910593477","957.047675332761","40.9949989318848","0.000841444804297401"
"0.0205939391803906","962.942543429607","41.1949996948242","0.00084820929646591"
"0.0206817364994818","965.256494855653","41.3950004577637","0.000849266745187672"
"0.0207854973841605","970.585718185022","41.5950012207031","0.00085622194478853"
"0.0208828714676201","973.717565819581","41.7949981689453","0.000856331513835279"
"0.0209818428242946","978.216049851402","41.9949989318848","0.0008596357725392"
"0.0210840064357585","982.505751358919","42.1949996948242","0.000863700640946077"
"0.0211765909912138","985.747259215234","42.3950004577637","0.000868590571436349"
"0.0212883336586863","990.877579319556","42.5950012207031","0.000875908279870307"
"0.0213841104689311","994.163653792521","42.7949981689453","0.000875463988127803"
"0.0214990453911931","999.484315062534","42.9949989318848","0.00088148247979959"
"0.0215836481638546","1001.56456617615","43.1949996948242","0.000880115229969177"
"0.0216937935581123","1007.4340774049","43.3950004577637","0.000889147156881586"
"0.0217799958956289","1009.68644786558","43.5950012207031","0.000887232706341233"
"0.0218901389982463","1015.36989895832","43.7949981689453","0.000892276391565734"
"0.021981128572127","1018.06991144534","43.9949989318848","0.000897857179960573"
"0.0220800999288015","1022.69781429743","44.1949996948242","0.000902969184708342"
"0.0221790712854759","1026.66127938947","44.3950004577637","0.000906187435291253"
"0.0222764453689355","1030.42364585663","44.5950012207031","0.000909507807090285"
"0.022388188036408","1035.92026842342","44.7949981689453","0.000915403696011723"
"0.0224871571014423","1038.99569428222","44.9949989318848","0.000918493829585069"
"0.0225941102409105","1043.96059100898","45.1949996948242","0.00091913011780753"
"0.0226819075600017","1046.24150166751","45.3950004577637","0.000924913501518221"
"0.022793647935834","1052.39674418478","45.5950012207031","0.000929404256932298"
"0.0228798502733506","1054.61321985815","45.7949981689453","0.000932943480369804"
"0.0229915906491829","1060.93333690303","45.9949989318848","0.000938394504638689"
"0.0230825802230635","1063.42994559534","46.1949996948242","0.00093911952230489"
"0.0231879360893169","1068.58704957765","46.3950004577637","0.000945874131775065"
"0.0232805229364124","1071.72230008195","46.5950012207031","0.000946991377983125"
"0.023377897019872","1075.98664472138","46.7949981689453","0.000952824891323048"
"0.0234880424141297","1081.07294705901","46.9949989318848","0.000956831466132504"
"0.0235918010071683","1085.0410224907","47.1949996948242","0.000961150491759584"
"0.0236971568734216","1089.5970259982","47.3950004577637","0.000963998427609986"
"0.0237833592109382","1092.22985925027","47.5950012207031","0.000966737653778712"
"0.0238919073319811","1097.8788425656","47.7949981689453","0.000970264774491446"
"0.0239765123962828","1100.28862319445","47.9949989318848","0.00097277984960375"
"0.0240898500453299","1106.27899118411","48.1949996948242","0.000981921345562909"
"0.0241808396192106","1108.95452496298","48.3950004577637","0.000980352861078009"
"0.0242893877402535","1114.60317896833","48.5950012207031","0.00098755498490971"
"0.0243787800409193","1117.16224678595","48.7949981689453","0.000987671643718307"
"0.0244857331803875","1122.33998752671","48.9949989318848","0.000995370194106913"
"0.0245878967918514","1126.51673571272","49.1949996948242","0.000997660258797723"
"0.02469165538489","1130.75594302403","49.3950004577637","0.00100385592290197"
"0.0247922240147792","1134.72357937576","49.5950012207031","0.00100569618159106"
"0.0248832135886599","1138.20208064426","49.7949981689453","0.00100999594311776"
"0.0249917617097028","1143.50550802556","49.9949989318848","0.00101573449661717"
"0.0250779617555791","1146.02220462637","50.1949996948242","0.00101710410970153"
"0.0251912994046263","1152.0636156622","50.3950004577637","0.00102298624878181"
"0.0252774994505027","1154.47701870077","50.5950012207031","0.00102697764147498"
"0.0253876448447603","1160.07287334009","50.7949981689453","0.00103156915744382"
"0.0254770394370664","1162.78221627641","50.9949989318848","0.0010323709450565"
"0.0255871848313241","1168.80847905338","51.1949996948242","0.00104031262414688"
"0.0256877511695731","1172.38500492451","51.3950004577637","0.00104383838419824"
"0.0258010888186203","1178.0492462687","51.5950012207031","0.00104860743066831"
"0.025892078392501","1180.59645892721","51.7949981689453","0.00105147685064553"
"0.0259846629479563","1184.43302990879","51.9949989318848","0.00105301260764392"
"0.026088423832635","1189.74260440963","52.1949996948242","0.00105819114157105"
"0.0261778161333009","1192.62494485295","52.3950004577637","0.00106263900034526"
"0.0262927510555628","1198.85175740484","52.5950012207031","0.00106812325339695"
"0.0263789511014392","1201.4009459232","52.7949981689453","0.00106929943772623"
"0.0264890964956969","1207.13906247183","52.9949989318848","0.00107709523959555"
"0.0265737015599986","1209.60142292672","53.1949996948242","0.00107693382218942"
"0.0266870392090458","1215.73537006559","53.3950004577637","0.00108462163051462"
"0.02678600827408","1219.42737396804","53.5950012207031","0.00108936124373095"
"0.026900943196342","1224.84309605091","53.7949981689453","0.00109377802213504"
"0.0269903354970078","1227.50578674074","53.9949989318848","0.00109768104345325"
"0.0270877118721076","1232.11843156398","54.1949996948242","0.00109860693770516"
"0.0271882782103567","1236.4838743658","54.3950004577637","0.00110468107326539"
"0.0272776705110226","1239.50353706879","54.5950012207031","0.00110524839744078"
"0.0273878159052802","1245.50323550776","54.7949981689453","0.00111262003103304"
"0.0274772104975863","1248.36043862296","54.9949989318848","0.00111482437405787"
"0.027587355891844","1254.27451646837","55.1949996948242","0.00111949566775093"
"0.0276735559377203","1256.68726088699","55.3950004577637","0.00112008590832826"
"0.0277884885683421","1263.15951914043","55.5950012207031","0.00112931298272589"
"0.0278826703970123","1266.02188144524","55.7949981689453","0.00113183027786463"
"0.0279976053192742","1272.1480349147","55.9949989318848","0.00113870412423862"
"0.0280869976199401","1274.57252472244","56.1949996948242","0.00113918257574276"
"0.0281907585046188","1279.80569930903","56.3950004577637","0.00114552655193577"
"0.0282865376065038","1283.52470662945","56.5950012207031","0.00114863845609095"
"0.0283823144167486","1287.51759007928","56.7949981689453","0.0011534622870844"
"0.0284892675562168","1292.81991976067","56.9949989318848","0.00116052340343045"
"0.0285754676020932","1295.70094296408","57.1949996948242","0.00116216350167139"
"0.0286856129963508","1301.58274843191","57.3950004577637","0.00117077111707923"
"0.0287718130422272","1304.32216834597","57.5950012207031","0.00116949216701002"
"0.0288899402192786","1311.31550475024","57.7949981689453","0.00117719107546741"
"0.0289857193211636","1313.98006152993","57.9949989318848","0.00118076560448665"
"0.0291006519517854","1320.21071603153","58.1949996948242","0.00118693047467579"
"0.0291836597428723","1322.05331511301","58.3950004577637","0.00119018625086687"
"0.0292890156091257","1327.86640456601","58.5950012207031","0.00119286961830588"
"0.029383199729436","1331.32459838603","58.7949981689453","0.00120034058017777"
"0.0294837660676851","1335.76314800236","58.9949989318848","0.00120156510379239"
"0.0295875269523638","1340.56371905147","59.1949996948242","0.0012059958468789"
"0.029681708781034","1343.99798301329","59.3950004577637","0.00121183193831404"
"0.0297854673740725","1349.47407859162","59.5950012207031","0.00121465065575197"
"0.0298732646931637","1352.4008758816","59.7949981689453","0.00121935596597916"
"0.0299881996154257","1359.46007428091","59.9949989318848","0.00122442636313467"
"0.0300823814440959","1362.3946652403","60.1949996948242","0.00122620782693005"
"0.0302005063295071","1368.54518764793","60.3950004577637","0.00123421753908867"
"0.030283514120594","1370.53235380854","60.5950012207031","0.00123773649583321"
"0.0303920645332771","1376.26684794744","60.7949981689453","0.00124286647563375"
"0.0304798618523683","1379.0422724188","60.9949989318848","0.00124493998032628"
"0.0305836204454068","1384.38269228732","61.1949996948242","0.00125101297006642"
"0.0306857840568707","1389.10631457222","61.3950004577637","0.00125542022384095"
"0.0307815631587557","1393.38383161065","61.5950012207031","0.00125814054397807"
"0.0308837267702196","1398.20833251796","61.7949981689453","0.00126691308586609"
"0.0309763113256749","1401.74391418217","61.9949989318848","0.00127136789117463"
"0.0310912462479369","1408.28971833008","62.1949996948242","0.00127564323241052"
"0.0311870230581817","1411.09511000919","62.3950004577637","0.00127928765645566"
"0.0312987657256542","1417.23202093784","62.5950012207031","0.00128680581179279"
"0.0313833707899559","1419.29284276291","62.7949981689453","0.00128729364469897"
"0.0314935138925734","1425.56005067177","62.9949989318848","0.00129520424341922"
"0.0315813112116646","1428.27444302771","63.1949996948242","0.00129772662313464"
"0.0316882643511328","1434.1820444436","63.3950004577637","0.00130381207366833"
"0.031782446179803","1437.86713283657","63.5950012207031","0.00130765630009283"
"0.0318814175364774","1442.43608920309","63.7949981689453","0.00131346789962341"
"0.0319819838747265","1447.00636280951","63.9949989318848","0.00132046771459428"
"0.0320777629766115","1450.77388846628","64.1949996948242","0.00132129671543426"
"0.0321911006256586","1456.99554182856","64.3949966430664","0.00132829166066972"
"0.0322884747091182","1460.55318726111","64.5950012207031","0.00133331020946585"
"0.0323986201033759","1466.04432132831","64.7949981689453","0.0013401699479299"
"0.0324832251676776","1468.28812972963","64.995002746582","0.0013421661097659"
"0.0325917732887205","1474.71439435653","65.1949996948242","0.00134992302536568"
"0.0326779733345968","1477.27368171413","65.3949966430664","0.00135450601929755"
"0.0327897160020694","1483.52903446388","65.5950012207031","0.00135880971958083"
"0.0328823005575247","1486.95067487665","65.7949981689453","0.00136380177128723"
"0.0329844641689886","1491.63796329428","65.995002746582","0.00137074615721092"
"0.0330786459976587","1495.77881669298","66.1949996948242","0.00137426253586025"
"0.0331760200811183","1500.36083568852","66.3949966430664","0.00138025889888142"
"0.0332893577301655","1506.60005224948","66.5950012207031","0.00138692914734697"
"0.0333915213416294","1510.61785348744","66.7949981689453","0.00139137750741747"
"0.033496879499523","1515.54828243679","66.995002746582","0.00139510027691172"
"0.0335830795453993","1518.09384854542","67.1949996948242","0.00139681771800919"
"0.033693224939657","1524.77620656307","67.3949966430664","0.00140645191660994"
"0.0337794249855334","1527.15514182423","67.5950012207031","0.0014080980304064"
"0.0338911653613657","1533.49874964734","67.7949981689453","0.00141580839706475"
"0.0339805599536717","1536.61808350284","67.995002746582","0.00142090844231526"
"0.0340875108014998","1542.26728635816","68.1949996948242","0.00142431195768506"
"0.0341800976485953","1545.80857606193","68.3949966430664","0.00143144139355437"
"0.0342822612600592","1550.96699728414","68.5950012207031","0.00143330206216394"
"0.0343860198530977","1555.90412220299","68.7949981689453","0.001441139328398"
"0.0344913780109913","1560.5490394038","68.995002746582","0.00144847415251965"
"0.0345951366040298","1565.46772296403","69.1949996948242","0.00145507464918682"
"0.0346845289046957","1568.35566167693","69.3949966430664","0.0014570433113405"
"0.0347930793173787","1574.42495429066","69.5950012207031","0.00146626902507677"
"0.0348792793632551","1576.98654681809","69.7949981689453","0.00147068014599412"
"0.0349926170123022","1583.63718130812","69.995002746582","0.00147634651282744"
"0.0350788170581786","1586.3843948916","70.1949996948242","0.0014816711388169"
"0.0351857701976468","1592.22042627287","70.3949966430664","0.00148943521579229"
"0.0352751624983127","1595.4484324202","70.5950012207031","0.00149267000915285"
"0.0353821156377809","1601.13890879241","70.7949981689453","0.00149903160232985"
"0.0354858765224596","1606.14068823639","70.995002746582","0.00150491896921431"
"0.0355928273702876","1611.25399399199","71.1949996948242","0.00150999939229567"
"0.0356902014537472","1614.9478639843","71.3949966430664","0.00151765576218196"
"0.0357811910276279","1618.65106442591","71.5950012207031","0.00152255786701076"
"0.035889741440311","1624.9378113933","71.7949981689453","0.00152893593135165"
"0.0359791337409768","1627.75999788114","71.995002746582","0.00153287483116165"
"0.0360924713900239","1634.55530922029","72.1949996948242","0.00154137380850157"
"0.0361786714359003","1637.13435517641","72.3949966430664","0.00154408281366524"
"0.036288816830158","1643.73570294014","72.5950012207031","0.0015531757554978"
"0.0363766141492492","1646.57161067695","72.7949981689453","0.00155648416779957"
"0.0364851622702921","1652.64836765012","72.995002746582","0.00156745997850607"
"0.0365857309001813","1656.99997943298","73.1949996948242","0.00157114980567254"
"0.0366974712760136","1662.8966038497","73.3949966430664","0.00158141692664922"
"0.0367900581231091","1666.26840868622","73.5950012207031","0.00158145287675475"
"0.0368858349333539","1670.39784600578","73.7949981689453","0.00158748834088672"
"0.0369864035632432","1675.39183178035","73.995002746582","0.00159367147258366"
"0.037075795863909","1678.74695157813","74.1949996948242","0.00160075751051681"
"0.037190730786171","1685.60307549271","74.3949966430664","0.00160845899706941"
"0.037278525813622","1688.45336309844","74.5950012207031","0.00161247538296344"
"0.0373886712078797","1694.94801443019","74.7949981689453","0.0016198043347571"
"0.0374748712537561","1697.20784925031","74.995002746582","0.00162190204489918"
"0.0375882089028032","1704.16880350701","75.1949996948242","0.00163194573095699"
"0.0376839880046882","1707.94994064276","75.3949966430664","0.0016391426269845"
"0.0377957306721607","1713.81187774208","75.5950012207031","0.00164839798881577"
"0.0378867202460414","1717.07709591661","75.7949981689453","0.00165129419233775"
"0.0379856893110756","1721.72354989731","75.995002746582","0.00165822454196526"
"0.0380878529225395","1726.91556073699","76.1949996948242","0.00166682420824618"
"0.0381788424964202","1730.23050471779","76.3949966430664","0.0016707361812839"
"0.0382873929091033","1736.1777331007","76.5950012207031","0.00167941863306681"
"0.0383751879365543","1739.25612274928","76.7949981689453","0.001683857396894"
"0.0384869283123866","1746.23420112469","76.995002746582","0.00169289476645186"
"0.0385747256314778","1749.12905534707","77.1949996948242","0.00169785946170345"
"0.0386912555353144","1756.29187661859","77.3949966430664","0.00170795026961274"
"0.0387854373639846","1759.27246120452","77.5950012207031","0.00171315658967722"
"0.0389003722862465","1765.92430316446","77.7949981689453","0.00172305633208538"
"0.0389865746237631","1768.33057115357","77.995002746582","0.00172311949541822"
"0.0390871409620122","1773.31500693886","78.1949996948242","0.00173108939032848"
"0.039182917772257","1777.85685011742","78.3949966430664","0.0017391168626986"
"0.0392802941473568","1781.99386156641","78.5950012207031","0.00174403586837382"
"0.0393888445600398","1788.00761056432","78.7949981689453","0.00175490927140918"
"0.0394782368607056","1791.01893074794","78.995002746582","0.00175839843683121"
"0.039583592726959","1796.86495119846","79.1949996948242","0.00176700612385281"
"0.0396713900460502","1799.78988239858","79.3949966430664","0.0017714378695319"
"0.0397895149314615","1807.01197946565","79.5950012207031","0.00178403243758004"
"0.0398852917417063","1810.52582667149","79.7949981689453","0.00178893855277918"
"0.0400018262288232","1817.06504461989","79.995002746582","0.0017976933344557"
"0.0400848340199102","1818.79578807978","80.1949996948242","0.00180174552722775"
"0.0401933798493128","1824.61008500269","80.3949966430664","0.00180984604562904"
"0.0402827721499787","1828.02920070565","80.5950012207031","0.0018161881598644"
"0.0403817435066531","1832.60617028157","80.7949981689453","0.00182125741119981"
"0.0404839094097572","1837.55602851946","80.995002746582","0.00183168251212232"
"0.0405764962568527","1841.52059131142","81.1949996948242","0.00183764521667814"
"0.0406850420862554","1847.40129907933","81.3949966430664","0.0018459763313739"
"0.0407728394053466","1850.40636237342","81.5950012207031","0.00184978890451823"
"0.0408877743276085","1857.0709376524","81.7949981689453","0.00186035264967244"
"0.0409819561562787","1860.37347762413","81.995002746582","0.00186468284704546"
"0.0410984860601153","1867.49798916854","82.1949996948242","0.0018766056780619"
"0.0411846883976319","1869.52478229617","82.3949966430664","0.00188265861595035"
"0.0412948337918895","1875.60362489918","82.5950012207031","0.00189118695493025"
"0.0413826265277004","1878.37926891052","82.7949981689453","0.00189725192392971"
"0.0414895819588088","1884.11387281942","82.995002746582","0.00190630347301128"
"0.0415853587690536","1888.32882096255","83.1949996948242","0.00191431963040794"
"0.0416795405977237","1892.25836712714","83.3949966430664","0.00192118681670262"
"0.0417817065008278","1897.48385781431","83.5950012207031","0.00192902336679912"
"0.0418758883294979","1901.34600520397","83.7949981689453","0.00193685576329778"
"0.0419924182333346","1908.08961487701","83.995002746582","0.00194624260798515"
"0.0420881950435793","1911.4259640062","84.1949996948242","0.00195271606184909"
"0.042198340437837","1916.94563827125","84.3949966430664","0.00196334741038901"
"0.0422813482289239","1919.1996552818","84.5950012207031","0.00196816257611797"
"0.0423946881696113","1926.22142211393","84.7949981689453","0.00198004344147337"
"0.0424824854887025","1928.62582401318","84.995002746582","0.00198597707084424"
"0.0425910313181051","1934.52332658982","85.1949996948242","0.00199583828505165"
"0.0426836181652006","1937.98788706937","85.3949966430664","0.00200272537997051"
"0.0427857794850243","1943.05838252819","85.5950012207031","0.00201100192498416"
"0.0428831558601241","1947.27859963093","85.7949981689453","0.00201924022825207"
"0.0429757427072196","1950.98465409232","85.995002746582","0.00202687754887926"
"0.043087483083052","1957.33462857496","86.1949996948242","0.00203804113085411"
"0.043188049421301","1961.27537127871","86.3949966430664","0.00204333668165862"
"0.0432981948155587","1966.98911888917","86.5950012207031","0.00205589200536845"
"0.0433827975882203","1968.85257426908","86.7949981689453","0.00206136272342025"
"0.0434913480009033","1975.1162695382","86.995002746582","0.00207064415265872"
"0.0435759507735649","1977.64800462787","87.1949996948242","0.00207826342661938"
"0.0436892907142522","1984.75144033386","87.3949966430664","0.00208862206997629"
"0.0437818775613477","1987.97911717122","87.5950012207031","0.0020988932013233"
"0.043885633862746","1993.28320317248","87.7949981689453","0.00210620639809063"
"0.0439798156914162","1997.31417680944","87.995002746582","0.00211411112448289"
"0.0440819815945203","2001.80464763187","88.1949996948242","0.00212465080741507"
"0.0441905320072033","2007.30961271802","88.3949966430664","0.00213588141986558"
"0.0442910983454524","2011.31643695681","88.5950012207031","0.00214431250736477"
"0.0443948592301311","2016.29077390285","88.7949981689453","0.00215403035083258"
"0.0444826565492224","2018.79748143441","88.995002746582","0.00216076505167857"
"0.0445943969250547","2025.43176019567","89.1949996948242","0.00217637599113133"
"0.0446789996977162","2027.542417597","89.3949966430664","0.00218305368742752"
"0.0447907400735485","2034.05046086775","89.5950012207031","0.00219111367244288"
"0.0448769424110651","2036.44432484779","89.7949981689453","0.0021991991519554"
"0.0449854928237481","2042.53985248955","89.995002746582","0.00221284500994228"
"0.0450796746524183","2045.89683837718","90.1949996948242","0.00221979455205641"
"0.0451834309538166","2050.76074671153","90.3949966430664","0.00222979125949026"
"0.04528878682007","2055.69798140037","90.5950012207031","0.00224189240875925"
"0.0453957422511784","2060.50546795896","90.7949981689453","0.0022518796631773"
"0.0454947136078529","2064.60120589106","90.995002746582","0.00226100253955989"
"0.045580911362089","2067.00011929072","91.1949996948242","0.00226939466917579"
"0.0456894617747721","2072.91298966621","91.3949966430664","0.00228352950588895"
"0.0457772590938633","2075.53737062892","91.5950012207031","0.0022909448238724"
"0.0458921940161253","2082.14837815193","91.7949981689453","0.00230122211400244"
"0.0459783917703614","2084.33455730758","91.995002746582","0.00231184085852129"
"0.0460853472014698","2090.01603254047","92.1949996948242","0.00232445705392376"
"0.0461731399372807","2092.83602362847","92.3949966430664","0.00233333615708077"
"0.0462816903499637","2098.87447087452","92.5950012207031","0.00234524910539887"
"0.0463870462162171","2103.55769780246","92.7949981689453","0.00235823711942273"
"0.0464955966289001","2108.76628391089","92.995002746582","0.0023726766010541"
"0.0465913734391449","2112.063774463","93.1949996948242","0.00238174089738424"
"0.0466839602862404","2115.27169270184","93.3949966430664","0.00239423248485119"
"0.0467909111340684","2120.81990716475","93.5950012207031","0.00240588533200734"
"0.046877113471585","2123.11892987192","93.7949981689453","0.00241525756748848"
"0.0469904488289919","2129.30468844689","93.995002746582","0.00242919217213974"
"0.0470782461480832","2131.77143970145","94.1949996948242","0.00243662568001722"
"0.0471883915423408","2137.77695594998","94.3949966430664","0.0024511102783149"
"0.047276188861432","2140.59892289784","94.5950012207031","0.00246176354066417"
"0.0473847392741151","2146.3592129848","94.7949981689453","0.00247532145695864"
"0.0474837106307895","2149.74012873064","94.995002746582","0.00248521962386417"
"0.0475938560250472","2155.38450170631","95.1949996948242","0.00249987437644621"
"0.047689632835292","2158.43896149669","95.3949966430664","0.0025118155405842"
"0.0477854096455368","2162.04578388554","95.5950012207031","0.00252425599582933"
"0.0478875755486409","2166.8510750443","95.7949981689453","0.00253516821352046"
"0.047980157812456","2169.65174661375","95.995002746582","0.00254565361322556"
"0.0480903032067137","2175.24672309315","96.1949996948242","0.0025622167291787"
"0.0481749105626556","2177.40041033124","96.3949966430664","0.00257045059239374"
"0.0482850559569133","2183.34994388398","96.5950012207031","0.00258499821079675"
"0.0483712537111494","2185.5244874205","96.7949981689453","0.00259651857250421"
"0.0484877836149861","2191.88258488252","96.995002746582","0.00261317048951485"
"0.0485851599900859","2195.03078824585","97.1949996948242","0.00262588193121286"
"0.0486953053843435","2200.53750965188","97.3949966430664","0.00263910526803907"
"0.0487846976850094","2202.7454232659","97.5950012207031","0.00265288919734761"
"0.0488836690416838","2207.11031721776","97.7949981689453","0.0026667625006237"
"0.0489858303615075","2211.81440044413","97.995002746582","0.00268076843257597"
"0.0490832067366073","2215.07917953869","98.1949996948242","0.00269323094485797"
"0.0491901575844354","2220.18326461499","98.3949966430664","0.00270834975457919"
"0.0492795544683816","2222.55978493633","98.5950012207031","0.00272279396271846"
"0.0493896998626393","2228.34554166138","98.7949981689453","0.0027387446378299"
"0.0494758976168755","2230.30471647409","98.995002746582","0.00274929047954511"
"0.0495908325391374","2236.70650239283","99.1949996948242","0.0027682827341033"
"0.0496866093493822","2239.417821189","99.3949966430664","0.00278072376225848"
"0.0498015442716442","2245.11729870054","99.5950012207031","0.00279976099025546"
"0.0498877466091608","2246.72784401946","99.7949981689453","0.00281122979005857"
"0.0499915029105591","2251.20097118319","99.995002746582","0.00282705958114981"
"0.0500840897576546","2254.28814243111","100.194999694824","0.00284465679974024"
"0.0501830611143291","2258.1524852206","100.394996643066","0.0028570714740332"
"0.0502900165454375","2263.1075026481","100.595001220703","0.00287357586670638"
"0.0503825988092526","2265.87897539975","100.794998168945","0.00288599541073474"
"0.050487954675506","2270.66450796","100.995002746582","0.00290357658784382"
"0.0505757519945972","2272.99975476444","101.194999694824","0.00291648310541329"
"0.0506938814632888","2279.35346142679","101.394996643066","0.00293813595423607"
"0.0507864637271039","2281.3220764588","101.595001220703","0.00294968582081102"
"0.0508998036677912","2286.88807366037","101.794998168945","0.00296963712679017"
"0.0509844064404528","2288.18072508319","101.995002746582","0.00298372985461477"
"0.0510913618715612","2293.35725835404","102.194999694824","0.00299928207078758"
"0.0511839441353763","2295.65606152122","102.394996643066","0.0030167417909664"
"0.0512845150569058","2299.81414880864","102.595001220703","0.00302986257689396"
"0.0513834818302998","2303.53227796912","102.794998168945","0.00304828449949901"
"0.05147766365897","2306.93712357316","102.995002746582","0.00306576942771996"
"0.0515830241085037","2312.01200983165","103.194999694824","0.00308418075148911"
"0.0516772059371739","2314.44451284878","103.394996643066","0.00310116524278282"
"0.0517921362761555","2320.35518782444","103.595001220703","0.00312241361711145"
"0.0518879176696806","2322.63467147307","103.794998168945","0.00313982463993616"
"0.0520012530270876","2327.94731953369","103.995002746582","0.00316105009786286"
"0.0520842608181745","2328.47377641411","104.194999694824","0.00317453067130079"
"0.0521944062124322","2333.83713821092","104.394996643066","0.00319687645482706"
"0.0522822035315234","2335.77194408546","104.595001220703","0.00321324735945897"
"0.0523875593977768","2340.39348027803","104.794998168945","0.00323045528567154"
"0.0524849357728766","2343.46857682686","104.995002746582","0.00325018802646724"
"0.0525807125831214","2346.79307079694","105.194999694824","0.00326678895448357"
"0.0526812789213704","2350.67168368536","105.394996643066","0.00328684453009151"
"0.0527754607500406","2353.30791980718","105.595001220703","0.00330274536202874"
"0.0528903956723025","2358.84713313076","105.794998168945","0.00332579324681928"
"0.052989367028977","2361.27568442819","105.995002746582","0.00334340077779058"
"0.05309791744166","2365.96901019536","106.194999694824","0.0033669152978155"
"0.0531825202143216","2366.9196183239","106.394996643066","0.00338256662742667"
"0.0532942605901539","2372.37057657412","106.595001220703","0.00340352969255122"
"0.0533804629276705","2373.41844091534","106.794998168945","0.00342280009493789"
"0.0534874137754985","2378.38223994218","106.995002746582","0.00344163479923278"
"0.053580000622594","2380.47423644491","107.194999694824","0.00346217591610671"
"0.0536805669608431","2384.42595614784","107.394996643066","0.00348366720429585"
"0.0537811332990921","2387.88195456803","107.595001220703","0.00350199545610799"
"0.0538785096741919","2390.76122145158","107.794998168945","0.00352418454873603"
"0.053987060086875","2395.42842196071","107.995002746582","0.00354481675830765"
"0.0540860314435494","2398.13996029687","108.194999694824","0.00356491157825391"
"0.0541945772729521","2402.70068391401","108.394996643066","0.00358966444334837"
"0.0542839695736179","2403.82450908953","108.595001220703","0.00360886982044454"
"0.0543941149678756","2408.93759530515","108.794998168945","0.00363556169959768"
"0.0544803173053922","2409.67810366948","108.995002746582","0.00365391888336726"
"0.0545936526627991","2415.16594463692","109.194999694824","0.00367737840402754"
"0.0546798550003157","2416.29899049174","109.394996643066","0.00369801032714414"
"0.0547836158849944","2420.41470656234","109.595001220703","0.0037178421813782"
"0.0548777977136646","2423.09704608069","109.794998168945","0.00373913438332553"
"0.0549799590334883","2426.70935696913","109.995002746582","0.00375989492474799"
"0.055090104427746","2430.88500745522","110.194999694824","0.00378984465689112"
"0.0551922703308501","2433.76207893893","110.394996643066","0.00381126776878451"
"0.0552928366690991","2436.69996299808","110.595001220703","0.0038343210962205"
"0.0553806339881904","2437.92916736567","110.794998168945","0.00385505986706112"
"0.0554923743640227","2442.85959631502","110.995002746582","0.0038792100307847"
"0.0555801716831139","2444.09209378236","111.194999694824","0.00390017452818437"
"0.0556935070405208","2449.09936172594","111.394996643066","0.00392898817970161"
"0.0557797093780374","2450.09058475142","111.595001220703","0.00395071436101057"
"0.0558882597907204","2454.62254863072","111.794998168945","0.00397502408018262"
"0.0559776520913863","2456.20477329178","111.995002746582","0.0039984076902615"
"0.056081412976065","2459.99578972678","112.194999694824","0.0040208474310357"
"0.0561867688423184","2463.17516776777","112.394996643066","0.00404699447273284"
"0.0562921247085718","2466.96947730253","112.595001220703","0.00407046974841945"
"0.0563926910468209","2469.20022307483","112.794998168945","0.00409718225233433"
"0.0564836783290613","2470.62064676805","112.995002746582","0.00411710978254647"
"0.0565890387785951","2474.62505606701","113.194999694824","0.00414761724262168"
"0.0566752365328313","2475.5124366803","113.394996643066","0.00416664215305263"
"0.0567885764735186","2481.00686384725","113.595001220703","0.00419517651092129"
"0.0568779687741845","2482.36252324534","113.794998168945","0.00422000385432203"
"0.0569865146035871","2487.03850535381","113.995002746582","0.0042490523989591"
"0.057077506469108","2488.11798345266","114.194999694824","0.00427142969253803"
"0.0571892468449403","2492.62074851416","114.394996643066","0.00429835875645119"
"0.0572882182016147","2494.34369830464","114.595001220703","0.00432406064704075"
"0.0573951690494428","2497.68334053358","114.794998168945","0.00435393418214746"
"0.0574893508781129","2499.48598333806","114.995002746582","0.00438158310753638"
"0.0575851322716381","2501.58105340056","115.194999694824","0.00440434625603288"
"0.0576904881378914","2505.12333103426","115.394996643066","0.00443520576933282"
"0.0577814754201319","2506.41971463681","115.595001220703","0.00445677296810336"
"0.0578916208143896","2510.32906312292","115.794998168945","0.00448110760886251"
"0.0579762281703315","2511.11128408411","115.995002746582","0.00450670580273333"
"0.0580879685461638","2515.59275376721","116.194999694824","0.0045356039584827"
"0.0581773608468297","2516.57651243326","116.394996643066","0.00455984722008914"
"0.0582906962042366","2521.35984959366","116.595001220703","0.00459037702365624"
"0.0583880725793365","2523.15568665866","116.794998168945","0.00461805058417725"
"0.0584998129551688","2526.69137809286","116.995002746582","0.00464656832765451"
"0.058589209839115","2527.24396023132","117.194999694824","0.00467364778045536"
"0.0586865816309344","2529.55813119735","117.394996643066","0.00469959373072552"
"0.0587871479691835","2532.19348915923","117.595001220703","0.00472810746383245"
"0.0588813297978536","2533.79657011872","117.794998168945","0.00475373487611573"
"0.0589898802105367","2537.81283457679","117.995002746582","0.00478340388233517"
"0.0590776775296279","2538.20361574741","118.194999694824","0.00480802726975869"
"0.0591862279423109","2542.35819039509","118.394996643066","0.00483596350953687"
"0.0592724256965471","2543.0205425253","118.595001220703","0.00486308277958608"
"0.0593889556003837","2547.90838071785","118.794998168945","0.00489095542634889"
"0.0594879269570582","2548.02803000885","118.995002746582","0.00491623049895242"
"0.0597848410270815","-6.5705083991008","119.075996398926","-0.00310211369536788"