File: Material Science Lab/ASEN1022_Jan28_Ductile_Data.csv
"File Path: C:\Users\Administrator\Desktop\New folder\1022\Test Run 1 01-28-20 12 42 51 PM\DAQ- Crosshead, … - (Timed).csv   "
"Test: MTS EM Tension (Extensometer)_ASEN1022_cast 2"
"Test Run: Test Run 1"
"Date: 1/28/2020 12:38:11 PM"
""
""
"Crosshead ","Load ","Time ","Extensometer "
"in","lbf","sec","in"
"0.000662466845824383","165.966176452038","0.19200000166893","8.48156714065534E-05"
"0.00173199172365465","281.788871823674","0.391999989748001","0.000215690893737057"
"0.00277916831147718","372.011105768606","0.592000007629395","0.000318510236558193"
"0.00380080385320622","452.899103350251","0.791999995708466","0.000405888185494004"
"0.00481286148474676","526.228119760152","0.991999983787537","0.000479473325015526"
"0.00581214895130934","593.302030402788","1.19200003147125","0.000547041942243552"
"0.00681782150036091","653.023931193121","1.39199995994568","0.000604754823716504"
"0.00782828300450672","709.075617424366","1.59200000762939","0.00065396572007178"
"0.0088275704710693","762.165050658303","1.79200005531311","0.000703606657032107"
"0.00982685793763188","812.854198367683","1.99199998378754","0.000748173974217906"
"0.0108357227414729","862.540267892472","2.19199991226196","0.000794110904488067"
"0.0118350107809455","910.983466685695","2.39199995994568","0.000837712581787354"
"0.0128406833299971","960.139017840365","2.59200000762939","0.000881988287758537"
"0.0138383740962549","1007.60992893168","2.79200005531311","0.000924495563637942"
"0.0148312764803285","1053.25097426056","2.99200010299683","0.000966015429048997"
"0.0158273711191916","1098.21484851034","3.19199991226196","0.00100613316873044"
"0.0168234657580546","1143.6832256422","3.39199995994568","0.0010460845496566"
"0.0178227526517072","1188.94940644926","3.59200000762939","0.0010872838718956"
"0.0188236368185745","1235.04742425379","3.79200005531311","0.00113038453935759"
"0.0198277132402314","1280.64686675579","3.99200010299683","0.00117230887926279"
"0.0208301935344934","1326.52644227674","4.19199991226196","0.00121213644000474"
"0.0218342688103302","1372.47594128243","4.39200019836426","0.00125534259452939"
"0.022831959576588","1417.90776500704","4.59200000762939","0.00129868381259794"
"0.0238376321256395","1465.72434180237","4.79199981689453","0.00134601692465596"
"0.0248369201651122","1513.12170699921","4.99200010299683","0.00139221381286056"
"0.0258378031861594","1561.54981241857","5.19199991226196","0.0014403550145418"
"0.0268338989708426","1609.42072535981","5.39200019836426","0.00148712423988471"
"0.0278299924638856","1656.33016294334","5.59200000762939","0.00153285964904536"
"0.0288260882485687","1705.25201378558","5.79199981689453","0.00158159639072186"
"0.0298285685428308","1754.13039571108","5.99200010299683","0.00162910538616473"
"0.0308246620358738","1803.44555243376","6.19199991226196","0.00167648862785198"
"0.0318287396033507","1853.63579553064","6.39200019836426","0.00172851845648646"
"0.0328280253511832","1903.33876963416","6.59200000762939","0.00177723657858639"
"0.0338336979002347","1955.70015339783","6.79199981689453","0.00183272048190243"
"0.0348345832129222","2006.61674453011","6.99200010299683","0.00188375774387813"
"0.035825889469601","2057.52674946289","7.19199991226196","0.0019378642282104"
"0.0368363492550167","2110.75773110119","7.39200019836426","0.00199284683523414"
"0.0378372345677042","2162.65017746011","7.59200000762939","0.00204730537279113"
"0.0388365226071768","2215.70530757162","7.79199981689453","0.00210362873255554"
"0.0398326161002198","2266.96284429827","7.99200010299683","0.00215983120829974"
"0.0408255196301135","2319.54464620537","8.19200038909912","0.00221661418515045"
"0.0418216131231564","2373.48957187","8.39200019836426","0.00227690208244951"
"0.0428209011626291","2426.67993861134","8.59200000762939","0.00233539319060941"
"0.0438201892021017","2481.26767734764","8.79199981689453","0.00239609200764066"
"0.0448258617511532","2535.40030969816","8.99199962615967","0.00246276355515359"
"0.0458235502257709","2588.55686728205","9.19200038909912","0.00252183487796496"
"0.0468324173212521","2644.14395202322","9.39200019836426","0.00259055400599073"
"0.0478380898703036","2697.91851466065","9.59200000762939","0.00265482534685605"
"0.0488389728913509","2752.25268471601","9.79199981689453","0.00272289594070707"
"0.0498382609308235","2806.67840294449","9.99199962615967","0.00279107137709695"
"0.0508359494054411","2861.30521979785","10.1920003890991","0.00286368915800181"
"0.0518256583889052","2915.6475128326","10.3920001983643","0.00293449625669883"
"0.0528233514468032","2969.79661068188","10.5920000076294","0.00300898544827667"
"0.0538210445047012","3023.70904442894","10.7919998168945","0.00308524750999916"
"0.0548203279608934","3079.15474542075","10.9919996261597","0.00316978439800515"
"0.055826000509945","3133.8575231084","11.1920003890991","0.00325065981789206"
"0.0568252885494176","3186.91726355957","11.3920001983643","0.0033375986312758"
"0.0578341556448988","3241.6907331219","11.5920000076294","0.0034335888505136"
"0.0588350386659461","3293.80996428377","11.7919998168945","0.00352524958851593"
"0.059831132158989","3345.85762541103","11.9919996261597","0.00362350681281509"
"0.060835209726466","3396.07673801574","12.1920003890991","0.00373277851924902"
"0.0618344977659386","3444.17443575994","12.3920001983643","0.00384539344227015"
"0.0628321862405562","3490.82953627259","12.5920000076294","0.00397336665141272"
"0.0638394583544628","3533.63983305427","12.7919998168945","0.00411054738439752"
"0.0648291673379268","3572.68831221875","12.9919996261597","0.00426446854899542"
"0.0658316453405487","3607.4379789664","13.1920003890991","0.00444637780173088"
"0.0668245488704424","3636.64338297085","13.3920001983643","0.00464984164921581"
"0.0678254318914897","3663.62704234232","13.5920000076294","0.00489364810357618"
"0.0688295094589666","3684.40737994013","13.7919998168945","0.00517110099216674"
"0.0698303924800139","3701.71196051924","13.9919996261597","0.00548784691642413"
"0.070845644085074","3717.2400235519","14.1920003890991","0.00584859175948558"
"0.0718465271061213","3728.13447569289","14.3920001983643","0.00622622770950286"
"0.072839430636015","3739.00126579597","14.5920000076294","0.00662483331311025"
"0.0738435036202115","3746.87923856373","14.7919998168945","0.00704878503016717"
"0.0748411966781095","3754.73042745351","14.9919996261597","0.00748808901779002"
"0.0758436746807314","3761.81410456099","15.1920003890991","0.00795208657431732"
"0.0768381731921998","3766.34365350047","15.3920001983643","0.00842462220929534"
"0.0778262917773696","3771.28110772929","15.5920000076294","0.00890710241689281"
"0.0788335593079958","3775.59506840499","15.7919998168945","0.00940920307491649"
"0.0798280578194641","3779.66446153906","15.9919996261597","0.00990231592010149"
"0.0808385153132395","3785.21267600197","16.1919994354248","0.0104045414725157"
"0.0818425928807165","3788.63574342464","16.3920001983643","0.0109069767100077"
"0.0828434804850441","3793.48142994036","16.5919990539551","0.0114095895496146"
"0.0838427639412364","3797.0950580687","16.7919998168945","0.0119102831405595"
"0.084843651545564","3801.06785361004","16.992000579834","0.0124118085968946"
"0.0858381500570324","3805.7414207787","17.1919994354248","0.0129038695792308"
"0.0868406234763739","3809.45823269928","17.3920001983643","0.0134043821306005"
"0.0878383211175522","3813.41522136181","17.5919990539551","0.0138917807709631"
"0.0888376045737445","3817.1465229213","17.7919998168945","0.0143831015535168"
"0.0898400871596468","3820.15158621539","17.992000579834","0.0148669252351777"
"0.0908313865414051","3822.52920423665","18.1919994354248","0.0153441776385839"
"0.0918322741457327","3826.20562080027","18.3920001983643","0.0158202979717345"
"0.0928299626203503","3829.86403508525","18.5919990539551","0.0162857404074038"
"0.0938292552431033","3834.38831506513","18.7919998168945","0.0167577082885239"
"0.0948365227737295","3838.20611537812","18.992000579834","0.0172309423008508"
"0.0958406003412065","3841.15673275631","19.1919994354248","0.0176961567183209"
"0.096846272890258","3845.09967085989","19.3920001983643","0.0181676490841008"
"0.0978535404208842","3848.99343200717","19.5919990539551","0.0186324257982939"
"0.098838459876344","3852.75371284449","19.7919998168945","0.0190824993490058"
"0.0998425374438209","3856.23166526303","19.992000579834","0.0195478443899669"
"0.100835440973715","3858.985574816","20.1919994354248","0.0199972602399433"
"0.101834724429907","3862.96144391711","20.3920001983643","0.020460043227168"
"0.102832412904524","3864.92061872983","20.5919990539551","0.0209165402453422"
"0.103823721452843","3867.95334406184","20.7919998168945","0.0213696135530674"
"0.104837378076329","3872.21066342179","20.992000579834","0.021829942193645"
"0.105838256514096","3875.30881166888","21.1919994354248","0.0222821286366152"
"0.106834350007139","3879.55471494969","21.3920001983643","0.0227307378292436"
"0.107844816667475","3882.17733959253","21.5919990539551","0.0231843702971759"
"0.108845695105242","3885.54157029962","21.7919998168945","0.0236354430030122"
"0.109841797764846","3889.67550818885","21.992000579834","0.0240857846756268"
"0.110844271184187","3893.2610351993","22.1919994354248","0.0245324368075299"
"0.111833984750932","3896.85753920893","22.3920001983643","0.024972193394091"
"0.112844442244707","3899.81254738678","22.5919990539551","0.025423275266488"
"0.113838940756175","3901.61848329102","22.7919998168945","0.0258689099101452"
"0.114830249304495","3905.27294585629","22.992000579834","0.0263154726680808"
"0.115829532760687","3907.29578726422","23.1919994354248","0.0267582244283747"
"0.116827230401865","3911.0990979383","23.3920001983643","0.0272037078237792"
"0.117836092914066","3914.40097929008","23.5919990539551","0.0276529311759793"
"0.118843360444692","3917.49561489744","23.7919998168945","0.0281007910022644"
"0.119839453937735","3921.01176727311","23.992000579834","0.0285436229699651"
"0.120843531505212","3923.51671848479","24.1919994354248","0.0289875022172341"
"0.12184441910954","3926.89499975083","24.3920001983643","0.0294327701984604"
"0.122842107584157","3930.60083467224","24.5919990539551","0.0298705284747728"
"0.123842995188485","3933.98394581791","24.7919998168945","0.0303109633868311"
"0.124834294570243","3936.69570369405","24.992000579834","0.0307467118946938"
"0.125841562100869","3938.96882068316","25.1919994354248","0.0311948192181198"
"0.126837664760473","3940.92316561624","25.3920001983643","0.0316318143782477"
"0.127828964142231","3944.38048127633","25.5919990539551","0.0320702005639731"
"0.128833041709708","3946.4573295202","25.7919998168945","0.0325150652165253"
"0.129833929314036","3949.88786130231","25.992000579834","0.0329509443478791"
"0.130839601863088","3952.92585559392","26.1919994354248","0.0333973948154452"
"0.131846869393714","3955.53311243792","26.3920001983643","0.0338348162206491"
"0.132834978812323","3958.48416889607","26.5919990539551","0.0342661533211395"
"0.133843850491084","3961.59241598241","26.7919998168945","0.0347093909091543"
"0.134839943984127","3963.78386409766","26.992000579834","0.0351395959393891"
"0.13583922744032","3968.22691428365","27.1919994354248","0.0355764536011055"
"0.136844899989371","3970.46314855554","27.3920001983643","0.0360133525123453"
"0.137828224463256","3971.6236369083","27.5919990539551","0.0364433490033225"
"0.138832302030733","3974.16766623705","27.7919998168945","0.0368821614341238"
"0.139831585486926","3975.94901366313","27.992000579834","0.0373211342797387"
"0.140829283128104","3979.62191758702","28.1919994354248","0.0377549211435959"
"0.141838145640305","3981.20172730825","28.3920001983643","0.0381897346622597"
"0.142837429096497","3984.15102744653","28.5919990539551","0.0386209021813757"
"0.143841506663974","3987.61317298626","28.7919998168945","0.0390618733372393"
"0.144843989249876","3989.03667023925","28.992000579834","0.0394934029355059"
"0.145832098668485","3992.38728946736","29.1919994354248","0.0399251800309133"
"0.146842565328821","3995.07621518522","29.3920001983643","0.0403651428650918"
"0.147841848785014","3997.52013428149","29.5919990539551","0.040802603228179"
"0.148847521334065","4000.73946859948","29.7919998168945","0.0412400635912662"
"0.149850003919968","4001.42575058789","29.992000579834","0.0416759748055827"
"0.150834923375427","4002.9739465515","30.1919994354248","0.0421053548453478"
"0.151829421886896","4004.99195807979","30.3920001983643","0.042539047751957"
"0.152828714509649","4007.29229802686","30.5919990539551","0.0429731210708384"
"0.153827997965841","4010.4589427488","30.7919998168945","0.0434075473023095"
"0.154838464626177","4011.7625711708","30.992000579834","0.0438484405424065"
"0.155844128008668","4014.36060733549","31.1919994354248","0.0442826101101759"
"0.156841816483285","4016.84887350843","31.3920001983643","0.0447166467628141"
"0.157845903217323","4019.31430752309","31.5919990539551","0.0451551841967923"
"0.158837211765642","4020.91826664251","31.7919998168945","0.0455821350979523"
"0.159849255074432","4023.9141092573","31.992000579834","0.0460265574639472"
"0.160845348567475","4025.45967074111","32.1920013427734","0.0464566799951351"
"0.161835062134219","4027.30380660247","32.3919982910156","0.0468911887256531"
"0.162835958905107","4028.48976159332","32.5919990539551","0.0473281082616547"
"0.16382884410188","4029.98043808125","32.7919998168945","0.0477648627995623"
"0.164828145891193","4032.0682633243","32.992000579834","0.0482102384878777"
"0.165840189199983","4033.92644974461","33.1920013427734","0.0486519979679678"
"0.166829902766727","4036.06652550372","33.3919982910156","0.0490824871615866"
"0.167848344334937","4038.18069554479","33.5919990539551","0.04953388069705"
"0.168846032809554","4038.99606704349","33.7919998168945","0.0499676927689492"
"0.169843739617293","4042.55876189566","33.992000579834","0.0504089710045987"
"0.17084461805506","4043.81057888155","34.1920013427734","0.0508453634633558"
"0.171829528343959","4045.24944393339","34.3919982910156","0.0512788363725064"
"0.172843184967445","4048.30851406342","34.5919990539551","0.0517246428891782"
"0.173845676719908","4048.58557352259","34.7919998168945","0.0521629144928939"
"0.174832181990381","4050.28525207481","34.992000579834","0.0526038352326732"
"0.175834673742844","4050.25583371702","35.1920013427734","0.0530441830624042"
"0.176835552180611","4052.16846605324","35.3919982910156","0.0534823721670729"
"0.177836430618378","4054.39943136552","35.5919990539551","0.0539291457559063"
"0.178840517352416","4055.39438657073","35.7919998168945","0.0543695210853196"
"0.179828617604464","4057.612179484","35.992000579834","0.0548077101899883"
"0.180843869209524","4059.09187897276","36.1920013427734","0.0552604787095677"
"0.181844765980413","4060.11800885562","36.3919982910156","0.0557065235568196"
"0.18284564441818","4063.0620400343","36.5919990539551","0.0561534713103077"
"0.183846522855946","4063.29958229644","36.7919998168945","0.0565956707853149"
"0.18483942638584","4065.66095435892","36.992000579834","0.0570372836004327"
"0.185841899805182","4066.56326369109","37.1920013427734","0.057486449661628"
"0.186839606612921","4067.3399961527","37.3919982910156","0.0579311516077265"
"0.187827706864969","4067.90465299025","37.5919990539551","0.0583790572668154"
"0.188825395339587","4068.27523648239","37.7919998168945","0.0588298824755108"
"0.189831077055199","4069.85153356389","37.992000579834","0.0592758448237157"
"0.190838353752386","4071.92443008806","38.1920013427734","0.0597275179392827"
"0.191845612116451","4073.109067839","38.3919982910156","0.0601810976994906"
"0.19283692066477","4073.76724870952","38.5919990539551","0.060620799286687"
"0.193848982306681","4075.83663259396","38.7919998168945","0.0610792648237873"
"0.19484348081815","4076.44827098797","38.992000579834","0.0615252455051138"
"0.195837979329618","4079.02303591441","39.1920013427734","0.0619761807125384"
"0.196840452748959","4079.09153238926","39.3919982910156","0.0624320750293417"
"0.197834951260428","4080.05750831665","39.5919990539551","0.0628789448670632"
"0.198831044753471","4080.63226399344","39.7919998168945","0.0633371949899854"
"0.199836726469083","4080.81975113934","39.992000579834","0.0637960821888813"
"0.200824826721131","4081.69878923326","40.1920013427734","0.0642501936096141"
"0.201836888363042","4082.55323884903","40.3919982910156","0.0647099791314658"
"0.202836171819234","4082.57299744754","40.5919990539551","0.0651599335168877"
"0.203838663571698","4085.49902634757","40.7919998168945","0.0656202323661428"
"0.204844326954188","4085.36378971774","40.992000579834","0.0660801324700042"
"0.205830850557783","4085.88014775892","41.1920013427734","0.0665312510086443"
"0.206846102162844","4088.40178400935","41.3919982910156","0.0669953998134244"
"0.207851765545334","4088.72538594503","41.5919990539551","0.067456936148384"
"0.208843074093653","4090.1264901197","41.7919998168945","0.0679140037849663"
"0.209845547512995","4089.6795067133","41.992000579834","0.0683748480445874"
"0.210838451042889","4089.57237120135","42.1920013427734","0.0688310631910178"
"0.211832949554357","4090.45228745521","42.3919982910156","0.0692958628216128"
"0.2128290430474","4090.20332911392","42.5919990539551","0.069758687058361"
"0.213823541558868","4090.94098345847","42.7919998168945","0.0702187246606341"
"0.214838793163928","4091.9354995837","42.992000579834","0.0706929108494614"
"0.215839689934817","4092.07776149301","43.1920013427734","0.0711539751065411"
"0.216843758335733","4094.12826493886","43.3919982910156","0.0716249392492565"
"0.217847845069771","4093.71684700979","43.5919990539551","0.0720909809488363"
"0.218843938562814","4094.19456601387","43.7919998168945","0.072555125170336"
"0.219854386890028","4095.43145428089","43.992000579834","0.0730254384872364"
"0.220850480383071","4095.64792070462","44.1920013427734","0.0734847198482456"
"0.221833814023517","4096.2613154185","44.3919982910156","0.0739418562340338"
"0.22283309747971","4095.42311176152","44.5919990539551","0.0744110741469217"
"0.223830785954327","4095.07140870796","44.7919998168945","0.0748751083696921"
"0.224828474428945","4095.82882165102","44.992000579834","0.0753488728967239"
"0.225837346107706","4095.6242103864","45.1920013427734","0.0758180266436864"
"0.226835034582324","4095.80203777303","45.3919982910156","0.076283307518722"
"0.227850286187384","4096.62706903101","45.5919990539551","0.0767561553896764"
"0.228846379680427","4096.41762788675","45.7919998168945","0.0772204279430269"
"0.229837688228746","4097.17635806972","45.992000579834","0.0776800118005417"
"0.230843369944358","4097.25407522387","46.1920013427734","0.0781489822162887"
"0.231839463437401","4097.36428429559","46.3919982910156","0.0786100143904057"
"0.232843531838318","4098.30786714465","46.5919990539551","0.0790718715549923"
"0.233847600239234","4097.66505407298","46.7919998168945","0.0795344437113193"
"0.234829338898105","4096.53266683811","46.992000579834","0.0799875743100493"
"0.235833407299021","4095.84111589009","47.1920013427734","0.0804480839902022"
"0.236827905810489","4094.78951936915","47.3919982910156","0.080903167066377"
"0.237831992544527","4096.24111774002","47.5919990539551","0.0813645750694857"
"0.238839250908593","4095.37130032541","47.7919998168945","0.0818241497604396"
"0.239827369493762","4094.31136128509","47.992000579834","0.0822713954271529"
"0.240841026117248","4095.50917143505","48.1920013427734","0.0827260110087282"
"0.241849897796009","4094.38951751922","48.3919982910156","0.0831781332857731"
"0.242844396307478","4094.79830096849","48.5919990539551","0.0836205115087154"
"0.243845274745245","4093.36909567593","48.7919998168945","0.0840563906400692"
"0.244844558201437","4093.24659236514","48.992000579834","0.0844855690154973"
"0.245843841657629","4093.18204760999","49.1920013427734","0.0849227772981632"
"0.246843125113821","4091.01694429276","49.3919982910156","0.0853470607301382"
"0.247826458754267","4089.02922928219","49.5919990539551","0.0857628467602758"
"0.248830527155183","4087.66632506464","49.7919998168945","0.0861948667695438"
"0.249829828944497","4085.97103731209","49.992000579834","0.0866183710438529"
"0.250832302363839","4085.61889517856","50.1920013427734","0.0870367787103719"
"0.251839579061026","4083.35631610865","50.3919982910156","0.0874479172941972"
"0.252842052480367","4082.21734267428","50.5919990539551","0.0878515759644311"
"0.253847715862858","4080.3174436571","50.7919998168945","0.0882515863434771"
"0.254850207615321","4078.25991493178","50.992000579834","0.0886452626290284"
"0.255844706126789","4076.90886587335","51.1920013427734","0.0890327973188612"
"0.256847179546131","4073.77471306896","51.3919982910156","0.0894178295376029"
"0.257843273039174","4070.88205424642","51.5919990539551","0.089790926894217"
"0.258832986605918","4068.31431459946","51.7919998168945","0.0901581943181791"
"0.25983546002526","4064.12593079432","51.992000579834","0.0905254800752627"
"0.260826768573579","4059.38957519038","52.1920013427734","0.090891115851407"
"0.26183883021549","4055.61480471416","52.3919982910156","0.0912568799594021"
"0.262838113671682","4051.54014262047","52.5919990539551","0.0915925777480593"
"0.263837397127874","4048.22289346985","52.7919998168945","0.0919233255938986"
"0.264843078843487","4042.68521692615","52.992000579834","0.0922497834892958"
"0.26583917233653","4038.16884038568","53.1920013427734","0.0925684773077176"
"0.266843240737446","4032.85772910495","53.3919982910156","0.0928915894084324"
"0.267850517434633","4027.69195329329","53.5919990539551","0.0932125107011223"
"0.268838636019802","4022.44670400761","53.7919998168945","0.093519132159005"
"0.269847489365443","4016.01506065112","53.992000579834","0.0938395584574131"
"0.270849981117906","4008.6538850045","54.1920013427734","0.0941461615821743"
"0.271838081369954","4002.41675407339","54.3919982910156","0.0944525172097946"
"0.272835788177693","3993.69399144913","54.5919990539551","0.0947584970084232"
"0.273822293448167","3985.88495423618","54.7919998168945","0.095056969393778"
"0.274835950071652","3978.90490000092","54.992000579834","0.0953584942438706"
"0.275838423490994","3970.44690259676","55.1920013427734","0.0956469567448605"
"0.276837725280307","3963.45455412242","55.3919982910156","0.095940580019566"
"0.277844983644373","3952.96888543069","55.5919990539551","0.0962357982758462"
"0.278847475396836","3945.13350341972","55.7919998168945","0.0965188525059796"
"0.279849948816177","3936.54641650527","55.992000579834","0.0968045192059335"
"0.280850827253944","3927.25241084396","56.1920013427734","0.0970792685320058"
"0.281835755875965","3918.59902285449","56.3919982910156","0.0973508828942935"
"0.282841419258456","3908.00577957085","56.5919990539551","0.0976254213894681"
"0.283832727806775","3896.61033718751","56.7919998168945","0.0978904449945594"
"0.284828821299818","3886.42280379337","56.992000579834","0.0981592635558111"
"0.28583450301543","3874.5715964043","57.1920013427734","0.0984224996815516"
"0.286835381453197","3863.93751868373","57.3919982910156","0.0986785583902062"
"0.287844253131958","3852.19476404651","57.5919990539551","0.0989310513067199"
"0.288841941606576","3841.4640887332","57.7919998168945","0.0991742493306089"
"0.289833250154895","3830.55251247349","57.992000579834","0.0994116174218458"
"0.290835723574237","3817.92237722298","58.1920013427734","0.0996521204768673"
"0.291839791975153","3806.48390500288","58.3919982910156","0.0998824669825514"
"0.29284387870919","3794.63357577374","58.5919990539551","0.10011285932104"
"0.293851137073256","3782.2778655026","58.7919998168945","0.100334946755467"
"0.294839255658426","3768.8174300345","58.992000579834","0.100552496742311"
"0.295843324059342","3755.15677410146","59.1920013427734","0.100768140084514"
"0.296841030867081","3740.53848476041","59.3919982910156","0.100974396868484"
"0.297830726100704","3727.11756648934","59.5919990539551","0.101175465379057"
"0.298836407816316","3712.66964017548","59.7919998168945","0.101376827219574"
"0.299837286254083","3698.9523429267","59.992000579834","0.101569086665244"
"0.300836569710275","3684.43460289809","60.1920013427734","0.101758669475167"
"0.301847036370612","3669.99392140368","60.3919982910156","0.101937206579358"
"0.302839939900505","3654.67332365543","60.5919990539551","0.102111334567816"
"0.303848811579267","3639.31430641006","60.7919998168945","0.102281227605197"
"0.304854474961758","3623.52872297676","60.992000579834","0.102438690786169"
"0.30585375841795","3608.77673378576","61.1920013427734","0.102592542342196"
"0.306851465225689","3591.79290112254","61.3919982910156","0.102736136516717"
"0.307834780533013","3573.656044466","61.5919990539551","0.102866384178752"
"0.30883565897078","3554.6247819167","61.7919998168945","0.102992396889709"
"0.309833347445398","3534.162118675","61.992000579834","0.103104586427019"
"0.310827845956866","3514.61361992459","62.1920013427734","0.103209525214758"
"0.311839907598777","3492.0929888776","62.3919982910156","0.103304674115589"
"0.312843975999693","3469.50891077539","62.5919990539551","0.103381783224818"
"0.313849657715306","3443.52525602874","62.7919998168945","0.103447479965884"
"0.314852149467769","3414.0124960474","62.992000579834","0.103486969509697"
"0.315843458016088","3381.14538465823","63.1920013427734","0.103509675080734"
"0.316855519657999","3335.56690822464","63.3919982910156","0.103490269471576"
"0.317984106620466","98.9643641121069","63.5740013122559","0.0875898706543399"